#VRML_SIM R2020a utf8
WorldInfo {
  info [
    "World generated using the Open Street Map to Webots importer"
    "Author: David Mansolino <david.mansolino@epfl.ch>"
  ]
  northDirection 0 0 1
  gpsCoordinateSystem "WGS84"
  gpsReference 33.932367049999996 -117.63095125000001 0
  lineScale 2
}
Viewpoint {
  orientation 0.43636891634463876 -0.8630420137883028 -0.2544418426368516 5.094822710147891
  position 12.564596730974902 9.99724088128154 5.373202049795979
  near 3
  follow "SUGV:body"
  followType "Mounted Shot"
}
TexturedBackground {
}
TexturedBackgroundLight {
}
Floor {
  translation 0 -0.02 0
  size 688 390
  tileSize 990 715
  appearance PBRAppearance {
    baseColorMap ImageTexture {
      url [
        "C:/Users/Colin Keenan/OneDrive/GitHub/Cjkeenan/NGCP_UGV_2019-2020/MainCode/Prado_Airpark/satellite_image.png"
      ]
      filtering 6
    }
    roughness 1
    metalness 0
    textureTransform TextureTransform {
      rotation 3.14
      translation -167 66
    }
  }
}
Ramp30deg {
}
Solid {
  translation 0 1.23 0
  children [
    Shape {
      appearance PBRAppearance {
        emissiveColor 1 0 1
      }
      geometry Box {
        size 0.1 0.5 2
      }
    }
  ]
  boundingObject Box {
    size 0.1 0.5 2
  }
  recognitionColors [
    1 0 1
  ]
}
DEF SUGV Robot {
  translation 0 0.16 -2.29
  children [
    Camera {
      translation 0 0.0499992 0.16
      rotation 0 1 0 3.14159
      children [
        DEF camera Shape {
          appearance Appearance {
            material Material {
              diffuseColor 0 0 0
            }
          }
          geometry Box {
            size 0.015 0.015 0.015
          }
        }
      ]
      boundingObject USE camera
      physics Physics {
      }
      fieldOfView 1.0472
      width 1296
      height 976
      recognition Recognition {
        frameThickness 10
      }
    }
    TouchSensor {
      translation 0 0 0.16
      scale 0.458998 0.458998 0.458998
      children [
        DEF Bumper Shape {
          appearance Appearance {
            material Material {
              diffuseColor 0 0 0
            }
          }
          geometry Box {
            size 0.1 0.1 0.05
          }
        }
      ]
      boundingObject USE Bumper
      physics Physics {
      }
      translationStep 0.001
    }
    Compass {
      yAxis FALSE
    }
    GPS {
    }
    DEF Wheel_LB HingeJoint {
      jointParameters HingeJointParameters {
        anchor 0.13 -0.0499998 -0.11
      }
      device [
        RotationalMotor {
          name "Motor_LB"
          maxVelocity 60
        }
      ]
      endPoint Solid {
        translation 0.13 -0.0499998 -0.11
        rotation 0 0 1 1.5708
        children [
          Shape {
            appearance Appearance {
              material Material {
                diffuseColor 0 1 1
              }
            }
            geometry Cylinder {
              height 0.0254
              radius 0.0381
            }
          }
        ]
        name "Wheel_LB"
        boundingObject Cylinder {
          height 0.0254
          radius 0.0381
        }
        physics Physics {
        }
      }
    }
    DEF Wheel_RM HingeJoint {
      jointParameters HingeJointParameters {
        anchor 0.13 -0.05 0
      }
      endPoint Solid {
        translation 0.13 -0.05 0
        rotation 0 0 1 1.5708
        children [
          Shape {
            appearance Appearance {
              material Material {
                diffuseColor 0 1 0
              }
            }
            geometry Cylinder {
              height 0.0254
              radius 0.0381
            }
          }
        ]
        name "Wheel_RM"
      }
    }
    DEF Wheel_LF HingeJoint {
      jointParameters HingeJointParameters {
        anchor 0.13 -0.0500003 0.11
      }
      device [
        RotationalMotor {
          name "Motor_LF"
          maxVelocity 60
        }
      ]
      endPoint Solid {
        translation 0.13 -0.0500003 0.11
        rotation 0 0 1 1.5708
        children [
          Shape {
            appearance Appearance {
              material Material {
                diffuseColor 0 1 0
              }
            }
            geometry Cylinder {
              height 0.0254
              radius 0.0381
            }
          }
        ]
        name "Wheel_LF"
        boundingObject Cylinder {
          height 0.0254
          radius 0.0381
        }
        physics Physics {
        }
      }
    }
    DEF Wheel_RB HingeJoint {
      jointParameters HingeJointParameters {
        anchor -0.13 -0.0500008 -0.11
      }
      device [
        RotationalMotor {
          name "Motor_RB"
          maxVelocity 60
        }
      ]
      endPoint Solid {
        translation -0.13 -0.0500008 -0.11
        rotation 0 0 1 1.5708
        children [
          Shape {
            appearance Appearance {
              material Material {
                diffuseColor 0 1 1
              }
            }
            geometry Cylinder {
              height 0.0254
              radius 0.0381
            }
          }
        ]
        name "Wheel_RB"
        boundingObject Cylinder {
          height 0.0254
          radius 0.0381
        }
        physics Physics {
        }
      }
    }
    DEF Wheel_LM HingeJoint {
      jointParameters HingeJointParameters {
        anchor -0.13 -0.0500008 0
      }
      endPoint Solid {
        translation -0.13 -0.0500008 0
        rotation 0 0 1 1.5708
        children [
          Shape {
            appearance Appearance {
              material Material {
                diffuseColor 0 1 0
              }
            }
            geometry Cylinder {
              height 0.0254
              radius 0.0381
            }
          }
        ]
        name "Wheel_LM"
      }
    }
    DEF Wheel_RF HingeJoint {
      jointParameters HingeJointParameters {
        anchor -0.13 -0.0500008 0.11
      }
      device [
        RotationalMotor {
          name "Motor_RF"
          maxVelocity 60
        }
      ]
      endPoint Solid {
        translation -0.13 -0.0500008 0.11
        rotation 0 0 1 1.5708
        children [
          Shape {
            appearance Appearance {
              material Material {
                diffuseColor 0 1 0
              }
            }
            geometry Cylinder {
              height 0.0254
              radius 0.0381
            }
          }
        ]
        name "Wheel_RF"
        boundingObject Cylinder {
          height 0.0254
          radius 0.0381
        }
        physics Physics {
        }
      }
    }
    DEF Body Solid {
      translation 0 0.0178 0
      children [
        Shape {
          appearance Appearance {
            material Material {
              diffuseColor 1 0 0
            }
          }
          geometry Box {
            size 0.2286 0.16 0.3048
          }
        }
      ]
      name "body"
      boundingObject Box {
        size 0.2286 0.16 0.3048
      }
      physics Physics {
      }
    }
  ]
  name "SUGV"
  boundingObject Transform {
    translation 0 0.0178 0
    children [
      Box {
        size 0.2286 0.16 0.3048
      }
    ]
  }
  physics Physics {
  }
  controller "<extern>"
}
