#VRML_SIM R2020a utf8
WorldInfo {
  gpsCoordinateSystem "WGS84"
}
Viewpoint {
  orientation 0.4410290203929964 0.8105749070719833 0.3853073100739714 4.621824917618156
  position -1.1496863762501577 1.9098792039726737 0.4608389248336419
  follow "SUGV:body"
  followType "Mounted Shot"
}
TexturedBackground {
}
TexturedBackgroundLight {
}
RectangleArena {
  floorSize 10 10
}
DEF SUGV Robot {
  translation 0 0.16 0
  rotation 0 1 0 -1.5707953071795862
  children [
    Compass {
      rotation 0 1 0 1.5708
    }
    GPS {
      rotation 0 1 0 1.57
    }
    DEF Wheel_RF HingeJoint {
      jointParameters HingeJointParameters {
        anchor 0.13 -0.0499998 -0.11
      }
      device [
        RotationalMotor {
          name "Motor_RF"
        }
      ]
      endPoint Solid {
        translation 0.13 -0.0499998 -0.11
        rotation 7.850447875279518e-17 -7.850447875279518e-17 1 1.5707999999999998
        children [
          Shape {
            appearance Appearance {
              material Material {
                diffuseColor 0 0 1
              }
            }
            geometry Cylinder {
              height 0.0254
              radius 0.0381
            }
          }
        ]
        name "Wheel_RF"
        boundingObject Cylinder {
          height 0.0254
          radius 0.0381
        }
        physics Physics {
        }
      }
    }
    DEF Wheel_RM HingeJoint {
      jointParameters HingeJointParameters {
        anchor 0.13 -0.05 0
      }
      endPoint Solid {
        translation 0.13 -0.05 0
        rotation 1.533290600640531e-19 -1.533290600640531e-19 1 1.5707999999999995
        children [
          Shape {
            appearance Appearance {
              material Material {
                diffuseColor 0 1 0
              }
            }
            geometry Cylinder {
              height 0.0254
              radius 0.0381
            }
          }
        ]
        name "Wheel_RM"
        boundingObject Cylinder {
          height 0.0254
          radius 0.0381
        }
        physics Physics {
        }
      }
    }
    DEF Wheel_RB HingeJoint {
      jointParameters HingeJointParameters {
        anchor 0.13 -0.0500003 0.11
      }
      device [
        RotationalMotor {
          name "Motor_RB"
        }
      ]
      endPoint Solid {
        translation 0.13 -0.0500003 0.11
        rotation 0 0 1 1.570799999999999
        children [
          Shape {
            appearance Appearance {
              material Material {
                diffuseColor 0 1 0
              }
            }
            geometry Cylinder {
              height 0.0254
              radius 0.0381
            }
          }
        ]
        name "Wheel_RB"
        boundingObject Cylinder {
          height 0.0254
          radius 0.0381
        }
        physics Physics {
        }
      }
    }
    DEF Wheel_LF HingeJoint {
      jointParameters HingeJointParameters {
        anchor -0.13 -0.0500008 -0.11
      }
      device [
        RotationalMotor {
          name "Motor_LF"
        }
      ]
      endPoint Solid {
        translation -0.13 -0.0500008 -0.11
        rotation -1.96261196881988e-16 -3.925223937639759e-17 1 1.5707999999999995
        children [
          Shape {
            appearance Appearance {
              material Material {
                diffuseColor 0 0 1
              }
            }
            geometry Cylinder {
              height 0.0254
              radius 0.0381
            }
          }
        ]
        name "Wheel_LF"
        boundingObject Cylinder {
          height 0.0254
          radius 0.0381
        }
        physics Physics {
        }
      }
    }
    DEF Wheel_LM HingeJoint {
      jointParameters HingeJointParameters {
        anchor -0.13 -0.0500008 0
      }
      endPoint Solid {
        translation -0.13 -0.0500008 0
        rotation -3.0665812012810623e-19 -7.666453003202656e-20 1 1.570799999999999
        children [
          Shape {
            appearance Appearance {
              material Material {
                diffuseColor 0 1 0
              }
            }
            geometry Cylinder {
              height 0.0254
              radius 0.0381
            }
          }
        ]
        name "Wheel_LM"
        boundingObject Cylinder {
          height 0.0254
          radius 0.0381
        }
        physics Physics {
        }
      }
    }
    DEF Wheel_LB HingeJoint {
      jointParameters HingeJointParameters {
        anchor -0.13 -0.0500008 0.11
      }
      device [
        RotationalMotor {
          name "Motor_LB"
        }
      ]
      endPoint Solid {
        translation -0.13 -0.0500008 0.11
        rotation -3.9252239376397585e-17 0 1 1.5707999999999995
        children [
          Shape {
            appearance Appearance {
              material Material {
                diffuseColor 0 1 0
              }
            }
            geometry Cylinder {
              height 0.0254
              radius 0.0381
            }
          }
        ]
        name "Wheel_LB"
        boundingObject Cylinder {
          height 0.0254
          radius 0.0381
        }
        physics Physics {
        }
      }
    }
    DEF Body Solid {
      translation 0 0.0178 0
      children [
        Shape {
          appearance Appearance {
            material Material {
              diffuseColor 1 0 0
            }
          }
          geometry Box {
            size 0.2286 0.16 0.3048
          }
        }
      ]
      name "body"
      boundingObject Box {
        size 0.2286 0.16 0.3048
      }
      physics Physics {
      }
    }
  ]
  name "SUGV"
  boundingObject Transform {
    translation 0 0.0178 0
    children [
      Box {
        size 0.2286 0.16 0.3048
      }
    ]
  }
  physics Physics {
  }
  controller "NGCP_2020_Robot_Controller"
}
