#VRML_SIM R2020a utf8
WorldInfo {
  gpsCoordinateSystem "WGS84"
}
Viewpoint {
  orientation 0.09693151831734902 0.9897109817129467 0.10524473114359961 4.563451450741979
  position -6.3261005530769205 1.9927966251672853 -2.986397497487052
}
DEF SUGV Robot {
  translation -0.671249 0.16 3.66394
  rotation 0 1 0 -1.5707953071795862
  children [
    TouchSensor {
      translation 0 -0.024 -0.165
      scale 0.458998 0.458998 0.458998
      children [
        DEF Bumper Shape {
          appearance Appearance {
            material Material {
              diffuseColor 0 0 0
            }
          }
          geometry Box {
            size 0.1 0.1 0.05
          }
        }
      ]
      boundingObject USE Bumper
      physics Physics {
      }
      translationStep 0.001
    }
    Camera {
      translation 0 0.07 0
      recognition Recognition {
      }
    }
    Compass {
      rotation 0 1 0 1.5708
    }
    GPS {
      rotation 0 1 0 1.57
    }
    DEF Wheel_RF HingeJoint {
      jointParameters HingeJointParameters {
        anchor 0.13 -0.0499998 -0.11
      }
      device [
        RotationalMotor {
          name "Motor_RF"
        }
      ]
      endPoint Solid {
        translation 0.13 -0.0499998 -0.11
        rotation 0 -1.1775671812919276e-16 1 1.5707999999999998
        children [
          Shape {
            appearance Appearance {
              material Material {
                diffuseColor 0 0 1
              }
            }
            geometry Cylinder {
              height 0.0254
              radius 0.0381
            }
          }
        ]
        name "Wheel_RF"
        boundingObject Cylinder {
          height 0.0254
          radius 0.0381
        }
        physics Physics {
        }
      }
    }
    DEF Wheel_RM HingeJoint {
      jointParameters HingeJointParameters {
        anchor 0.13 -0.05 0
      }
    }
    DEF Wheel_RB HingeJoint {
      jointParameters HingeJointParameters {
        anchor 0.13 -0.0500003 0.11
      }
      device [
        RotationalMotor {
          name "Motor_RB"
        }
      ]
      endPoint Solid {
        translation 0.13 -0.0500003 0.11
        rotation -7.850447875279521e-17 -7.850447875279521e-17 1 1.570799999999999
        children [
          Shape {
            appearance Appearance {
              material Material {
                diffuseColor 0 1 0
              }
            }
            geometry Cylinder {
              height 0.0254
              radius 0.0381
            }
          }
        ]
        name "Wheel_RB"
        boundingObject Cylinder {
          height 0.0254
          radius 0.0381
        }
        physics Physics {
        }
      }
    }
    DEF Wheel_LF HingeJoint {
      jointParameters HingeJointParameters {
        anchor -0.13 -0.0500008 -0.11
      }
      device [
        RotationalMotor {
          name "Motor_LF"
        }
      ]
      endPoint Solid {
        translation -0.13 -0.0500008 -0.11
        rotation -1.570089575055904e-16 -7.85044787527952e-17 1 1.570799999999999
        children [
          Shape {
            appearance Appearance {
              material Material {
                diffuseColor 0 0 1
              }
            }
            geometry Cylinder {
              height 0.0254
              radius 0.0381
            }
          }
        ]
        name "Wheel_LF"
        boundingObject Cylinder {
          height 0.0254
          radius 0.0381
        }
        physics Physics {
        }
      }
    }
    DEF Wheel_LM HingeJoint {
      jointParameters HingeJointParameters {
        anchor -0.13 -0.0500008 0
      }
    }
    DEF Wheel_LB HingeJoint {
      jointParameters HingeJointParameters {
        anchor -0.13 -0.0500008 0.11
      }
      device [
        RotationalMotor {
          name "Motor_LB"
        }
      ]
      endPoint Solid {
        translation -0.13 -0.0500008 0.11
        rotation -1.9626119688198792e-16 0 1 1.5707999999999995
        children [
          Shape {
            appearance Appearance {
              material Material {
                diffuseColor 0 1 0
              }
            }
            geometry Cylinder {
              height 0.0254
              radius 0.0381
            }
          }
        ]
        name "Wheel_LB"
        boundingObject Cylinder {
          height 0.0254
          radius 0.0381
        }
        physics Physics {
        }
      }
    }
    DEF Body Solid {
      translation 0 0.0178 0
      children [
        Shape {
          appearance Appearance {
            material Material {
              diffuseColor 1 0 0
            }
          }
          geometry Box {
            size 0.2286 0.16 0.3048
          }
        }
      ]
      name "body"
      boundingObject Box {
        size 0.2286 0.16 0.3048
      }
      physics Physics {
      }
    }
  ]
  name "SUGV(1)"
  boundingObject Transform {
    translation 0 0.0178 0
    children [
      Box {
        size 0.2286 0.16 0.3048
      }
    ]
  }
  physics Physics {
  }
  recognitionColors [
    0 0 0
  ]
  controller "NGCP_2020_Robot_Controll_Camera_Rec"
}
RectangleArena {
  floorSize 10 10
}
TexturedBackground {
}
TexturedBackgroundLight {
}
Solid {
  translation -0.391399 0.27 -2.04791
  scale 2 2 2
  children [
    Shape {
      appearance Appearance {
        material Material {
          diffuseColor 1 0 0
        }
      }
      geometry Box {
        size 0.1 0.1 0.1
      }
    }
  ]
  boundingObject Box {
    size 0.1 0.1 0.1
  }
  physics Physics {
  }
  recognitionColors [
    0.9 0 0
  ]
}
WoodenBox {
  translation 0.281511 0.3 -0.518987
  rotation 1 0 0 4.692820414042842e-06
}
DEF BUGV Robot {
  translation 0.0466059 0.04 -1.90661
  rotation 0 1 0 -1.5707953071795862
  children [
    DEF BUGV Transform {
      translation 0.07 0.04 0
      scale 2 2 2
      children [
        Solid {
          children [
            DEF diamond Transform {
              translation -0.095 0 -0.220575
              rotation 1 0 0 -0.261799
              children [
                Transform {
                  translation 0 -0.005 0
                  rotation 0 1 0 0.78539
                  children [
                    Shape {
                      appearance Appearance {
                        material Material {
                          diffuseColor 0 0.1 0.3
                        }
                      }
                      geometry Plane {
                        size 0.05 0.05
                      }
                    }
                  ]
                }
              ]
            }
            DEF Ramp_R Transform {
              translation -0.19 0 -0.2
              children [
                Transform {
                  rotation 1 0 0 -0.261799
                  children [
                    Shape {
                      appearance Appearance {
                        material Material {
                          diffuseColor 0 0.1 0.3
                        }
                      }
                      geometry Plane {
                        size 0.0985747062188375 0.3028649562213102
                      }
                    }
                  ]
                }
              ]
            }
            DEF Base Transform {
              translation -0.095 0.0149 0.145
              children [
                Shape {
                  appearance FlexibleAluminiumDuct {
                  }
                  geometry Box {
                    size 0.3 0.05 0.4
                  }
                }
              ]
            }
            DEF Ramp_L Transform {
              translation 0 0 -0.2
              children [
                Transform {
                  rotation 1 0 0 -0.261799
                  children [
                    Shape {
                      appearance Appearance {
                        material Material {
                          diffuseColor 0 0.1 0.3
                        }
                      }
                      geometry Plane {
                        size 0.0985747062188375 0.3028649562213102
                      }
                    }
                  ]
                }
              ]
            }
            DEF Ramp_M Transform {
              translation 0 0 -0.2
              children [
                Transform {
                  translation -0.095 0 0
                  rotation 1 0 0 -0.261799
                  children [
                    Shape {
                      appearance Appearance {
                        material Material {
                          diffuseColor 1 1 1
                        }
                      }
                      geometry Plane {
                        size 0.0985747062188375 0.3028649562213102
                      }
                    }
                  ]
                }
              ]
            }
          ]
          boundingObject USE Base
        }
      ]
    }
  ]
  boundingObject Transform {
    translation -0.115 0.0379 -0.393984
    rotation 1 0 0 -0.261799
    scale 2 2 2
    children [
      Box {
        size 0.3 0.005 0.3
      }
    ]
  }
}
